<?xml version="1.0"?>
<!--
  Robot: mecanum_robot
  Generated by: LinkForge v1.2.3
  https://github.com/arounamounchili/linkforge
  Date: 2026-02-28 18:07:18
-->
<robot name="mecanum_robot">
  <!-- Links -->
  <link name="base_link">
    <visual>
      <origin xyz="0 0 -0.000069" rpy="0 0 0" />
      <geometry>
        <mesh filename="meshes\base_link_visual.obj" />
      </geometry>
    </visual>
    <collision>
      <origin xyz="0 0 -0.000069" rpy="0 0 0" />
      <geometry>
        <box size="0.259997 0.179998 0.077499" />
      </geometry>
    </collision>
    <inertial>
      <mass value="5" />
      <inertia ixx="0.016002" ixy="0" ixz="0" iyy="0.030668" iyz="0" izz="0.041666" />
    </inertial>
  </link>
  <link name="rear_left_wheel">
    <visual>
      <origin xyz="0 0 0" rpy="0 0 0" />
      <geometry>
        <mesh filename="meshes\rear_left_wheel_visual.obj" />
      </geometry>
    </visual>
    <inertial>
      <mass value="1" />
      <inertia ixx="0.000688" ixy="0" ixz="0" iyy="0.000688" iyz="0" izz="0.000998" />
    </inertial>
  </link>
  <link name="front_left_wheel">
    <visual>
      <origin xyz="0 0 0" rpy="0 0 0" />
      <geometry>
        <mesh filename="meshes\front_left_wheel_visual.obj" />
      </geometry>
    </visual>
    <inertial>
      <mass value="1" />
      <inertia ixx="0.000688" ixy="0" ixz="0" iyy="0.000688" iyz="0" izz="0.000998" />
    </inertial>
  </link>
  <link name="rear_right_wheel">
    <visual>
      <origin xyz="0 0 0" rpy="0 0 0" />
      <geometry>
        <mesh filename="meshes\rear_right_wheel_visual.obj" />
      </geometry>
    </visual>
    <inertial>
      <mass value="1" />
      <inertia ixx="0.000688" ixy="0" ixz="0" iyy="0.000688" iyz="0" izz="0.000998" />
    </inertial>
  </link>
  <link name="front_right_wheel">
    <visual>
      <origin xyz="0 0 0" rpy="0 0 0" />
      <geometry>
        <mesh filename="meshes\front_right_wheel_visual.obj" />
      </geometry>
    </visual>
    <inertial>
      <mass value="1" />
      <inertia ixx="0.000688" ixy="0" ixz="0" iyy="0.000688" iyz="0" izz="0.000998" />
    </inertial>
  </link>
  <link name="base_footprint">
    <inertial>
      <mass value="1" />
      <inertia ixx="1" ixy="0" ixz="0" iyy="1" iyz="0" izz="1" />
    </inertial>
  </link>
  <link name="laser">
    <inertial>
      <mass value="1" />
      <inertia ixx="1" ixy="0" ixz="0" iyy="1" iyz="0" izz="1" />
    </inertial>
  </link>
  <link name="camera">
    <inertial>
      <mass value="1" />
      <inertia ixx="1" ixy="0" ixz="0" iyy="1" iyz="0" izz="1" />
    </inertial>
  </link>
  <!-- Joints -->
  <joint name="front_right_joint" type="continuous">
    <origin xyz="0.09 -0.071496 0.000175" rpy="1.570796 0 -3.141593" />
    <parent link="base_link" />
    <child link="front_right_wheel" />
    <axis xyz="0 0 1" />
  </joint>
  <joint name="rear_right_joint" type="continuous">
    <origin xyz="-0.09 -0.071496 0.000175" rpy="1.570796 0 -3.141593" />
    <parent link="base_link" />
    <child link="rear_right_wheel" />
    <axis xyz="0 0 1" />
  </joint>
  <joint name="front_left_joint" type="continuous">
    <origin xyz="0.09 0.071504 0.000175" rpy="1.570796 0 0" />
    <parent link="base_link" />
    <child link="front_left_wheel" />
    <axis xyz="0 0 1" />
  </joint>
  <joint name="rear_left_joint" type="continuous">
    <origin xyz="-0.09 0.071504 0.000175" rpy="1.570796 0 0" />
    <parent link="base_link" />
    <child link="rear_left_wheel" />
    <axis xyz="0 0 1" />
  </joint>
  <joint name="base_footprint_joint" type="fixed">
    <origin xyz="0 0 -0.038825" rpy="0 0 0" />
    <parent link="base_link" />
    <child link="base_footprint" />
  </joint>
  <joint name="laser_joint" type="fixed">
    <origin xyz="0.070733 0 0.086997" rpy="0 0 -1.570796" />
    <parent link="base_link" />
    <child link="laser" />
  </joint>
  <joint name="camera_joint" type="fixed">
    <origin xyz="0.081656 0.036685 0.067712" rpy="-1.570796 0 -1.570796" />
    <parent link="base_link" />
    <child link="camera" />
  </joint>
</robot>